<robot
  name="zhrobot">
  <link
    name="base_link">
    <inertial>
      <origin
        xyz="0.00012128 0.00014938 0.099776"
        rpy="0 0 0" />
      <mass
        value="3.8413" />
      <inertia
        ixx="0.012067"
        ixy="4.9E-07"
        ixz="0.00010217"
        iyy="0.011933"
        iyz="2.373E-05"
        izz="0.0062804" />
    </inertial>
    <visual>
      <origin
        xyz="0 0 0"
        rpy="0 0 0" />
      <geometry>
        <mesh
          filename="package://zhrobot/meshes/base_link.STL" />
      </geometry>
      <material
        name="gray">
        <color
          rgba="1 1 1 1" />
      </material>
    </visual>
    <collision>
      <origin
        xyz="0 0 0"
        rpy="0 0 0" />
      <geometry>
        <mesh
          filename="package://zhrobot/meshes/base_link.STL" />
      </geometry>
    </collision>
  </link>
  <link
    name="link2">
    <inertial>
      <origin
        xyz="-0.00016173 -0.002251 0.042306"
        rpy="0 0 0" />
      <mass
        value="3.555" />
      <inertia
        ixx="0.007827"
        ixy="-7.3E-07"
        ixz="2.938E-05"
        iyy="0.0079527"
        iyz="0.00035769"
        izz="0.0051663" />
    </inertial>
    <visual>
      <origin
        xyz="0 0 0"
        rpy="0 0 0" />
      <geometry>
        <mesh
          filename="package://zhrobot/meshes/link2.STL" />
      </geometry>
      <material
        name="gray">
        <color
          rgba="1 1 1 1" />
      </material>
    </visual>
    <collision>
      <origin
        xyz="0 0 0"
        rpy="0 0 0" />
      <geometry>
        <mesh
          filename="package://zhrobot/meshes/link2.STL" />
      </geometry>
    </collision>
  </link>
  <joint
    name="joint1"
    type="revolute">
    <origin
      xyz="0 0 0.2261"
      rpy="1.5708 0 0" />
    <parent
      link="base_link" />
    <child
      link="link2" />
    <axis
      xyz="0 -1 0" />
    <limit
      lower="-3.1416"
      upper="3.1416"
      effort="100"
      velocity="0.5" />
    <dynamics
      damping="0.5"
      friction="0.5" />
  </joint>
  <link
    name="bigarm">
    <inertial>
      <origin
        xyz="0.1875 1.73E-05 0.12277"
        rpy="0 0 0" />
      <mass
        value="0.87042" />
      <inertia
        ixx="0.0010539"
        ixy="1E-07"
        ixz="0"
        iyy="0.016125"
        iyz="2E-07"
        izz="0.016763" />
    </inertial>
    <visual>
      <origin
        xyz="0 0 0"
        rpy="0 0 0" />
      <geometry>
        <mesh
          filename="package://zhrobot/meshes/bigarm.STL" />
      </geometry>
      <material
        name="gray">
        <color
          rgba="1 1 1 1" />
      </material>
    </visual>
    <collision>
      <origin
        xyz="0 0 0"
        rpy="0 0 0" />
      <geometry>
        <mesh
          filename="package://zhrobot/meshes/bigarm.STL" />
      </geometry>
    </collision>
  </link>
  <joint
    name="joint2"
    type="revolute">
    <origin
      xyz="0 0 0"
      rpy="0 0 0" />
    <parent
      link="link2" />
    <child
      link="bigarm" />
    <axis
      xyz="0 0 -1" />
    <limit
      lower="-3.1416"
      upper="3.1416"
      effort="100"
      velocity="0.5" />
    <dynamics
      damping="0.5"
      friction="0.5" />
  </joint>
  <link
    name="link3">
    <inertial>
      <origin
        xyz="0.0001617 0.042309 -0.0022472"
        rpy="0 0 0" />
      <mass
        value="3.5547" />
      <inertia
        ixx="0.0078253"
        ixy="-2.94E-05"
        ixz="7E-07"
        iyy="0.0051655"
        iyz="0.0003572"
        izz="0.0079515" />
    </inertial>
    <visual>
      <origin
        xyz="0 0 0"
        rpy="0 0 0" />
      <geometry>
        <mesh
          filename="package://zhrobot/meshes/link3.STL" />
      </geometry>
      <material
        name="gray">
        <color
          rgba="1 1 1 1" />
      </material>
    </visual>
    <collision>
      <origin
        xyz="0 0 0"
        rpy="0 0 0" />
      <geometry>
        <mesh
          filename="package://zhrobot/meshes/link3.STL" />
      </geometry>
    </collision>
  </link>
  <joint
    name="joint3"
    type="revolute">
    <origin
      xyz="0.375 0 0"
      rpy="1.5708 0 0" />
    <parent
      link="bigarm" />
    <child
      link="link3" />
    <axis
      xyz="0 -1 0" />
    <limit
      lower="-3.1416"
      upper="3.1416"
      effort="100"
      velocity="0.5" />
    <dynamics
      damping="0.5"
      friction="0.5" />
  </joint>
  <link
    name="link4">
    <inertial>
      <origin
        xyz="-0.00027637 0.28564 -0.012939"
        rpy="0 0 0" />
      <mass
        value="4.0261" />
      <inertia
        ixx="0.042331"
        ixy="4.379E-05"
        ixz="-1.44E-05"
        iyy="0.01003"
        iyz="0.011181"
        izz="0.038178" />
    </inertial>
    <visual>
      <origin
        xyz="0 0 0"
        rpy="0 0 0" />
      <geometry>
        <mesh
          filename="package://zhrobot/meshes/link4.STL" />
      </geometry>
      <material
        name="gray">
        <color
          rgba="1 1 1 1" />
      </material>
    </visual>
    <collision>
      <origin
        xyz="0 0 0"
        rpy="0 0 0" />
      <geometry>
        <mesh
          filename="package://zhrobot/meshes/link4.STL" />
      </geometry>
    </collision>
  </link>
  <joint
    name="joint4"
    type="revolute">
    <origin
      xyz="0 0 -0.435"
      rpy="1.5708 0 0" />
    <parent
      link="link3" />
    <child
      link="link4" />
    <axis
      xyz="0 1 0" />
    <limit
      lower="-3.1416"
      upper="3.1416"
      effort="100"
      velocity="0.5" />
    <dynamics
      damping="0.5"
      friction="0.5" />
  </joint>
  <link
    name="link5">
    <inertial>
      <origin
        xyz="0.00034682 -0.042079 0.0021679"
        rpy="0 0 0" />
      <mass
        value="2.205" />
      <inertia
        ixx="0.0038576"
        ixy="3.25E-05"
        ixz="6.5E-07"
        iyy="0.0021613"
        iyz="0.0002071"
        izz="0.0038912" />
    </inertial>
    <visual>
      <origin
        xyz="0 0 0"
        rpy="0 0 0" />
      <geometry>
        <mesh
          filename="package://zhrobot/meshes/link5.STL" />
      </geometry>
      <material
        name="gray">
        <color
          rgba="1 1 1 1" />
      </material>
    </visual>
    <collision>
      <origin
        xyz="0 0 0"
        rpy="0 0 0" />
      <geometry>
        <mesh
          filename="package://zhrobot/meshes/link5.STL" />
      </geometry>
    </collision>
  </link>
  <joint
    name="joint5"
    type="revolute">
    <origin
      xyz="0 0 0"
      rpy="1.5708 0 0" />
    <parent
      link="link4" />
    <child
      link="link5" />
    <axis
      xyz="0 1 0" />
    <limit
      lower="-3.1416"
      upper="3.1416"
      effort="100"
      velocity="0.5" />
    <dynamics
      damping="0.5"
      friction="0.5" />
  </joint>
  <link
    name="link6">
    <inertial>
      <origin
        xyz="0.00030399 0.00036053 -0.10004"
        rpy="0 0 0" />
      <mass
        value="2.1217" />
      <inertia
        ixx="0.0037689"
        ixy="2.09E-06"
        ixz="3.728E-05"
        iyy="0.0037195"
        iyz="3.323E-05"
        izz="0.0019077" />
    </inertial>
    <visual>
      <origin
        xyz="0 0 0"
        rpy="0 0 0" />
      <geometry>
        <mesh
          filename="package://zhrobot/meshes/link6.STL" />
      </geometry>
      <material
        name="gray">
        <color
          rgba="1 1 1 1" />
      </material>
    </visual>
    <collision>
      <origin
        xyz="0 0 0"
        rpy="0 0 0" />
      <geometry>
        <mesh
          filename="package://zhrobot/meshes/link6.STL" />
      </geometry>
    </collision>
  </link>
  <joint
    name="joint6"
    type="revolute">
    <origin
      xyz="0 0 0.1878"
      rpy="0 0 0" />
    <parent
      link="link5" />
    <child
      link="link6" />
    <axis
      xyz="0 0 -1" />
    <limit
      lower="-3.1416"
      upper="3.1416"
      effort="100"
      velocity="0.5" />
    <dynamics
      damping="0.5"
      friction="0.5" />
  </joint>
</robot>